Workbook
Name Slicer_City1: #N/A
Name Slicer_Payment_Method1: #N/A

Sheet DATASET
A1: Order_ID | B1: New Date | C1: Month | D1: Days | E1: Customer_Name | F1: Customer_Type | G1: Customer_Segment | H1: City | I1: Pincode | J1: Payment_Method | K1: SKU | L1: Product_Name | M1: Category | O1: Qty | P1: Price | Q1: Discount | R1: Subtotal | S1: Tax | T1: Delivery_Fee | U1: Surge_Fee | V1: Sales | W1: Delivery_Status | X1: Delivery_Time
A2: O0001 | B2: 08-02-2025 | C2: =TEXT(B2,"mmmm") -> February | D2: =TEXT(B2,"dd") -> 08 | E2: Cust_0 | F2: Bulk | G2: Bakery | H2: DELHI | I2: 554151 | J2: UPI | K2: SKU0 | L2: Product_0 | M2: Veg | N2: =LEN(M2) -> 3 | O2: 2 | P2: 94 | Q2: 9.43 | R2: 179.07 | S2: 8.95 | T2: 0 | U2: 10 | V2: 198.02 | W2: Delivered | X2: 14
A3: O0002 | B3: 21-02-2025 | C3: =TEXT(B3,"mmmm") -> February | D3: =TEXT(B3,"dd") -> 21 | E3: Cust_1 | F3: Bulk | G3: Bakery | H3: DELHI | I3: 554151 | J3: UPI | K3: SKU1 | L3: Product_1 | M3: Essentials | N3: =LEN(M3) -> 10 | O3: 1 | P3: 1 | Q3: 1.84 | R3: 16.61 | S3: 0.83 | T3: 0 | U3: 0 | V3: 17.44 | W3: Cancelled | X3: 12
A4: O0003 | B4: 29-01-2025 | C4: =TEXT(B4,"mmmm") -> January | D4: =TEXT(B4,"dd") -> 29 | E4: Cust_2 | F4: Bulk | G4: Café | H4: DELHI | I4: 554151 | J4: UPI | K4: SKU2 | L4: Product_2 | M4: Fruits | N4: =LEN(M4) -> 6 | O4: 6 | P4: 59.27 | Q4: 2.96 | R4: 352.66 | S4: 17.63 | T4: 0 | U4: 0 | V4: 370.29 | W4: Delivered | X4: 12
A5: O0004 | B5: 15-01-2025 | C5: =TEXT(B5,"mmmm") -> January | D5: =TEXT(B5,"dd") -> 15 | E5: Cust_3 | F5: Bulk | G5: Bakery | H5: DELHI | I5: 554151 | J5: UPI | K5: SKU3 | L5: Product_3 | M5: Frozen | N5: =LEN(M5) -> 6 | O5: 2 | P5: 168.45 | Q5: 25.27 | R5: 311.63 | S5: 15.58 | T5: 0 | U5: 10 | V5: 337.21 | W5: Delivered | X5: 12
A6: O0005 | B6: 12-02-2025 | C6: =TEXT(B6,"mmmm") -> February | D6: =TEXT(B6,"dd") -> 12 | E6: Cust_4 | F6: Bulk | G6: Bakery | H6: DELHI | I6: 554151 | J6: NETBANKING | K6: SKU4 | L6: Product_4 | M6: snaks | N6: =LEN(M6) -> 5 | O6: 6 | P6: 52.47 | Q6: 7.87 | R6: 306.95 | S6: 15.35 | T6: 0 | U6: 0 | V6: 322.3 | W6: Delivered | X6: 12
A7: O0006 | B7: 08-01-2025 | C7: =TEXT(B7,"mmmm") -> January | D7: =TEXT(B7,"dd") -> 08 | E7: Cust_5 | F7: Bulk | G7: Café | H7: DELHI | I7: 554151 | J7: UPI | K7: SKU5 | L7: Product_5 | M7: Other | N7: =LEN(M7) -> 5 | O7: 5 | P7: 78.11 | Q7: 3.91 | R7: 386.64 | S7: 19.33 | T7: 30 | U7: 15 | V7: 450.97 | W7: Delivered | X7: 12 | Z7: =MEDIAN(X:X) -> 25
A8: O0007 | B8: 21-01-2025 | C8: =TEXT(B8,"mmmm") -> January | D8: =TEXT(B8,"dd") -> 21 | E8: Cust_6 | F8: Bulk | G8: Bakery | H8: DELHI | I8: 554151 | J8: COD | K8: SKU6 | L8: Product_6 | M8: Bakery | N8: =LEN(M8) -> 6 | O8: 1 | P8: 103.87 | Q8: 5.19 | R8: 98.68 | S8: 4.93 | T8: 20 | U8: 0 | V8: 123.61 | W8: Delivered | X8: 12
A9: O0008 | B9: 08-02-2025 | C9: =TEXT(B9,"mmmm") -> February | D9: =TEXT(B9,"dd") -> 08 | E9: Cust_7 | F9: Bulk | G9: Bakery | H9: DELHI | I9: 554151 | J9: UPI | K9: SKU7 | L9: Product_7 | M9: frozen | N9: =LEN(M9) -> 6 | O9: 3 | P9: 129.5 | Q9: 12.95 | R9: 375.55 | S9: 18.78 | T9: 20 | U9: 10 | V9: 424.33 | W9: Delivered | X9: 12
A10: O0009 | B10: 27-02-2025 | C10: =TEXT(B10,"mmmm") -> February | D10: =TEXT(B10,"dd") -> 27 | E10: Cust_8 | F10: Bulk | G10: Office | H10: DELHI | I10: 554151 | J10: UPI | K10: SKU8 | L10: Product_8 | M10: Snacks | N10: =LEN(M10) -> 6 | O10: 1 | P10: 131.89 | Q10: 0 | R10: 131.89 | S10: 6.59 | T10: 10 | U10: 0 | V10: 148.48 | W10: Delivered | X10: 12
A11: O0010 | B11: 19-01-2025 | C11: =TEXT(B11,"mmmm") -> January | D11: =TEXT(B11,"dd") -> 19 | E11: Cust_9 | F11: Bulk | G11: Cloud Kitchen | H11: DELHI | I11: 554151 | J11: WALLET | K11: SKU9 | L11: Product_9 | M11: DIARY | N11: =LEN(M11) -> 5 | O11: 1 | P11: 207.92 | Q11: 20.79 | R11: 187.13 | S11: 9.36 | T11: 30 | U11: 0 | V11: 226.49 | W11: Delivered | X11: 12
A12: O0011 | B12: 23-01-2025 | C12: =TEXT(B12,"mmmm") -> January | D12: =TEXT(B12,"dd") -> 23 | E12: Cust_10 | F12: New | G12: Household | H12: DELHI | I12: 554151 | J12: UPI | K12: SKU10 | L12: Product_10 | M12: DIARY | N12: =LEN(M12) -> 5 | O12: 3 | P12: 134.09 | Q12: 13.41 | R12: 388.86 | S12: 19.44 | T12: 20 | U12: 0 | V12: 428.3 | W12: Failed | X12: 12
A13: O0012 | B13: 11-01-2025 | C13: =TEXT(B13,"mmmm") -> January | D13: =TEXT(B13,"dd") -> 11 | E13: Cust_11 | F13: Bulk | G13: Cloud Kitchen | H13: DELHI | I13: 554151 | J13: UPI | K13: SKU11 | L13: Product_11 | M13: FRUITS | N13: =LEN(M13) -> 7 | O13: 6 | P13: 86.17 | Q13: 0 | R13: 517.02 | S13: 25.85 | T13: 10 | U13: 5 | V13: 557.87 | W13: Delivered | X13: 10
A14: O0013 | B14: 11-01-2025 | C14: =TEXT(B14,"mmmm") -> January | D14: =TEXT(B14,"dd") -> 11 | E14: Cust_12 | F14: Bulk | G14: Cloud Kitchen | H14: DELHI | I14: 554151 | J14: CARD | K14: SKU12 | L14: Product_12 | M14: Frozen | N14: =LEN(M14) -> 6 | O14: 3 | P14: 104.71 | Q14: 5.24 | R14: 308.89 | S14: 15.44 | T14: 10 | U14: 20 | V14: 354.33 | W14: Delivered | X14: 16
A15: O0014 | B15: 24-01-2025 | C15: =TEXT(B15,"mmmm") -> January | D15: =TEXT(B15,"dd") -> 24 | E15: Cust_13 | F15: Bulk | G15: Office | H15: DELHI | I15: 554151 | J15: UPI | K15: SKU13 | L15: Product_13 | M15: Baby | N15: =LEN(M15) -> 4 | O15: 4 | P15: 204.9 | Q15: 20.49 | R15: 799.11 | S15: 39.96 | T15: 0 | U15: 0 | V15: 839.07 | W15: Cancelled | X15: 16
A16: O0015 | B16: 22-02-2025 | C16: =TEXT(B16,"mmmm") -> February | D16: =TEXT(B16,"dd") -> 22 | E16: Cust_14 | F16: Returning | G16: Household | H16: DELHI | I16: 554151 | J16: WALLET | K16: SKU14 | L16: Product_14 | M16: Bakery | N16: =LEN(M16) -> 6 | O16: 3 | P16: 193.33 | Q16: 0 | R16: 579.99 | S16: 29 | T16: 30 | U16: 20 | V16: 658.99 | W16: Delivered | X16: 3
A17: O0016 | B17: 05-02-2025 | C17: =TEXT(B17,"mmmm") -> February | D17: =TEXT(B17,"dd") -> 05 | E17: Cust_15 | F17: Bulk | G17: Tea Stall | H17: DELHI | I17: 554151 | J17: COD | K17: SKU15 | L17: Product_15 | M17: Fruits | N17: =LEN(M17) -> 6 | O17: 3 | P17: 35.35 | Q17: 3.54 | R17: 102.51 | S17: 5.13 | T17: 30 | U17: 0 | V17: 137.64 | W17: Delivered | X17: 25
A18: O0017 | B18: 09-02-2025 | C18: =TEXT(B18,"mmmm") -> February | D18: =TEXT(B18,"dd") -> 09 | E18: Cust_16 | F18: Bulk | G18: Tea Stall | H18: DELHI | I18: 554151 | J18: UPI | K18: SKU16 | L18: Product_16 | M18: snaks | N18: =LEN(M18) -> 5 | O18: 2 | P18: 128.59 | Q18: 6.43 | R18: 250.75 | S18: 12.54 | T18: 0 | U18: 5 | V18: 268.29 | W18: Delivered | X18: 34
A19: O0018 | B19: 24-01-2025 | C19: =TEXT(B19,"mmmm") -> January | D19: =TEXT(B19,"dd") -> 24 | E19: Cust_17 | F19: Bulk | G19: Tea Stall | H19: DELHI | I19: 554151 | J19: PHONEPE | K19: SKU17 | L19: Product_17 | M19: Baby | N19: =LEN(M19) -> 4 | O19: 5 | P19: 145.22 | Q19: 7.26 | R19: 718.84 | S19: 35.94 | T19: 20 | U19: 5 | V19: 779.78 | W19: Returned | X19: 25
... A1501: O1500 | B1501: 21-01-2025 | C1501: =TEXT(B1501,"mmmm") -> January | D1501: =TEXT(B1501,"dd") -> 21 | E1501: Cust_299 | F1501: Bulk | G1501: Café | H1501: NEPAL | I1501: 524448 | J1501: Wallet | K1501: SKU99 | L1501: Product_99 | M1501: Essentials | N1501: =LEN(M1501) -> 10 | O1501: 1 | P1501: 198.94 | Q1501: 29.84 | R1501: 169.1 | S1501: 8.46 | T1501: 30 | U1501: 15 | V1501: 222.56 | W1501: Delivered | X1501: 23

Sheet PIVOTS AND CHARTS 
A1: TOP 10 ORDERS
A2: ORDERS | B2: SALES
A3: O0140 | B3: 1364.17
A4: O0265 | B4: 1539.18
A5: O0276 | B5: 1456.78
A6: O0753 | B6: 1541.46
A7: O0856 | B7: 1413.14
A8: O0860 | B8: 1370.47
A9: O0911 | B9: 1448.76
A10: O1013 | B10: 1555.44
A11: O1022 | B11: 1399.41
A12: O1477 | B12: 1688.83
A13: Grand Total | B13: 14777.64
A16: SALES OVER MONTHS
A18: MONTHS | B18: SALES
A19: January | B19: 282500.82
A20: February | B20: 270809.05
A21: March | B21: 10682.38
A22: Grand Total | B22: 563992.25
A31: SALES OVER DAYS
A33: DAYS | B33: SALES
A34: 01 | B34: 33179.46
A35: 02 | B35: 26284.59
A36: 05 | B36: 25134.15
A37: 08 | B37: 24444.61
A38: 13 | B38: 20151.24
A39: 22 | B39: 23268.94
A40: 23 | B40: 20450.79
A41: 26 | B41: 21970.33
A42: 27 | B42: 21158.87
A43: 28 | B43: 21945.21
A44: Grand Total | B44: 237988.19
A48: SALES OVER CUSTOMER SEGMENTS
A50: Row Labels | B50: Sum of Total
A51: Bakery | B51: 87989.5
A52: Café | B52: 96038.71
A53: Cloud Kitchen | B53: 87461.87
A54: Household | B54: 93946.4
A55: Office | B55: 103708.09
A56: Tea Stall | B56: 94847.68
...

Sheet KPI
I3: zz
H8: =COUNTBLANK(DATASET!I2:I1501) -> 0
E9: KPI
E11: TOTAL SALES | F11: =SUM(DATASET!V1:V1501) -> 563992.25
E12: TOTAL ORDERS | F12: =COUNTA(_xlfn.UNIQUE(DATASET!A2:A1501)) -> 1500
E13: TOTAL CUSTOMERS | F13: =COUNTA((_xlfn.UNIQUE(DATASET!E2:E1501))) -> 300
E14: TOTAL PRODUCTS | F14: =COUNTA(_xlfn.UNIQUE(DATASET!L2:L1501)) -> 200
E15: TOTAL QUANTITY | F15: =SUM(DATASET!O2:O1501) -> 4207
E16: AVERAGE SALES | F16: =AVERAGE(DATASET!V1:V1501) -> 375.99483

Sheet ZEPTO PROJECT
